#VRML_SIM R2022a utf8
WorldInfo {
}
Viewpoint {
  orientation -0.0885405801330455 -0.0022895712133285165 0.9960699390772533 2.8685327128547025
  position 0.964036745395286 -4.989239959164528 5.254687415970274
}
TexturedBackground {
  texture "mars"
}
TexturedBackgroundLight {
  luminosity 2
}
UnevenTerrain {
  appearance SandyGround {
    colorOverride 0.55 0.55 0.4
    textureTransform TextureTransform {
      scale 50 50
    }
  }
}
Robot {
  translation -5.594600788517188 -2.036059093541891 3.141278805801049
  rotation 0.07762681706495819 0.03445593127328004 -0.9963869058114195 0.6639792652002583
  children [
    DEF body Shape {
      appearance HammeredCopper {
      }
      geometry Box {
        size 0.7 0.5 0.2
      }
    }
    Solid {
      translation 0 0 0.19
      children [
        DEF panel Shape {
          appearance SolarCell {
          }
          geometry Box {
            size 0.8 0.5 0.01
          }
        }
        Solid {
          translation 0.3 -0.19 -0.05
          children [
            Shape {
              appearance Copper {
              }
              geometry Cylinder {
                height 0.1
                radius 0.02
              }
            }
          ]
          name "solar_panel_support1"
        }
        Solid {
          translation 0.3 0.19 -0.05
          children [
            Shape {
              appearance Copper {
              }
              geometry Cylinder {
                height 0.1
                radius 0.02
              }
            }
          ]
          name "solar_panel_support2"
        }
        Solid {
          translation -0.3 0.19 -0.05
          children [
            Shape {
              appearance Copper {
              }
              geometry Cylinder {
                height 0.1
                radius 0.02
              }
            }
          ]
          name "solar_panel_support3"
        }
        Solid {
          translation -0.3 -0.19 -0.05
          children [
            Shape {
              appearance Copper {
              }
              geometry Cylinder {
                height 0.1
                radius 0.02
              }
            }
          ]
          name "solar_panel_support4"
        }
      ]
      name "solar_panel"
    }
    Solid {
      translation -0.18 -0.24 0
      children [
        Solid {
          translation -0.00017766252744422228 -0.017340268664742475 0.05993637531167906
          rotation -0.9999999929357695 8.124469320562993e-05 -8.676267159571073e-05 1.5708626067521982
          children [
            DEF cylinder1 Shape {
              appearance DamascusSteel {
              }
              geometry Cylinder {
                height 0.09
                radius 0.02
              }
            }
            Solid {
              translation 0 0 -0.05
              children [
                DEF sphere1 Shape {
                  appearance BrushedSteel {
                  }
                  geometry Sphere {
                    radius 0.02
                  }
                }
                Solid {
                  translation 0 0.1 1.79608e-07
                  rotation -1 0 0 -1.5707953071795862
                  children [
                    DEF cylinder2 Shape {
                      appearance BrushedSteel {
                      }
                      geometry Cylinder {
                        height 0.2
                        radius 0.02
                      }
                    }
                    Solid {
                      translation 0 0 -0.11
                      children [
                        DEF sphere1 Shape {
                          appearance BrushedSteel {
                          }
                          geometry Sphere {
                            radius 0.02
                          }
                        }
                        Solid {
                          translation 0 -0.03 -9.99999e-08
                          rotation 1 0 0 1.5708
                          children [
                            DEF cylinder3 Shape {
                              appearance BrushedSteel {
                              }
                              geometry Cylinder {
                                height 0.06
                                radius 0.02
                              }
                            }
                            HingeJoint {
                              jointParameters HingeJointParameters {
                                position 148.2921028546053
                                axis 0 0 1
                                anchor -9.51224e-05 0.00113507 0.0800056
                              }
                              device [
                                RotationalMotor {
                                  name "wheel1_left"
                                }
                              ]
                              endPoint Solid {
                                translation -0.0016503963804031165 0.001647656576605211 0.07995424362107062
                                rotation 4.7202623174941005e-06 6.916601902295148e-07 0.9999999999886204 3.7907201396464796
                                children [
                                  DEF wheel Shape {
                                    appearance DamascusSteel {
                                    }
                                    geometry Cylinder {
                                      height 0.15
                                      radius 0.15
                                    }
                                  }
                                ]
                                boundingObject USE wheel
                                physics Physics {
                                  mass 1
                                }
                                linearVelocity 0.0002253352861464784 1.7915247459969288e-05 -1.2072545596240596e-05
                                angularVelocity -0.00042888916175704895 0.00040703570888819986 -0.00034403774949935705
                              }
                            }
                          ]
                          boundingObject USE cylinder3
                          physics DEF phy1 Physics {
                            mass 1
                          }
                        }
                      ]
                      name "solid(1)"
                      boundingObject USE sphere1
                      physics USE phy1
                    }
                  ]
                  boundingObject USE cylinder2
                  physics USE phy1
                }
              ]
              boundingObject USE sphere1
              physics USE phy1
            }
          ]
          boundingObject USE cylinder1
          physics USE phy1
        }
      ]
      name "wheel1_left_system"
      physics DEF phy1 Physics {
        mass 1
      }
    }
    Solid {
      translation 0.18 -0.24 0
      children [
        Solid {
          translation -0.0001757815149209252 -0.017333744024692788 0.0600545153188472
          rotation -0.9999999930027248 7.374603208071159e-05 -9.249904417794078e-05 1.5708786387286822
          children [
            DEF cylinder1 Shape {
              appearance DamascusSteel {
              }
              geometry Cylinder {
                height 0.09
                radius 0.02
              }
            }
            Solid {
              translation 0 0 -0.05
              children [
                DEF sphere1 Shape {
                  appearance BrushedSteel {
                  }
                  geometry Sphere {
                    radius 0.02
                  }
                }
                Solid {
                  translation 0 0.1 1.79608e-07
                  rotation -1 0 0 -1.5707953071795862
                  children [
                    DEF cylinder2 Shape {
                      appearance BrushedSteel {
                      }
                      geometry Cylinder {
                        height 0.2
                        radius 0.02
                      }
                    }
                    Solid {
                      translation 0 0 -0.11
                      children [
                        DEF sphere1 Shape {
                          appearance BrushedSteel {
                          }
                          geometry Sphere {
                            radius 0.02
                          }
                        }
                        Solid {
                          translation 0 -0.03 -9.99999e-08
                          rotation 1 0 0 1.5708
                          children [
                            DEF cylinder3 Shape {
                              appearance BrushedSteel {
                              }
                              geometry Cylinder {
                                height 0.06
                                radius 0.02
                              }
                            }
                            HingeJoint {
                              jointParameters HingeJointParameters {
                                position -163.50191715298755
                                axis 0 0 1
                                anchor 0.000341778 0.000558794 0.0800055
                              }
                              device [
                                RotationalMotor {
                                  name "wheel2_left"
                                }
                              ]
                              endPoint Solid {
                                translation -0.0002996414331823371 -8.119803683096524e-05 0.07995173580166282
                                rotation -2.9937244756106626e-05 1.488426411120982e-05 -0.9999999994411101 0.1283447938258864
                                children [
                                  DEF wheel Shape {
                                    appearance DamascusSteel {
                                    }
                                    geometry Cylinder {
                                      height 0.15
                                      radius 0.15
                                    }
                                  }
                                ]
                                boundingObject USE wheel
                                physics Physics {
                                  mass 1
                                }
                                linearVelocity -1.6116657907378837e-05 0.00014069274023108749 3.399982864606152e-06
                                angularVelocity -0.0004800960963874532 0.0003494308841475572 -0.00034977452345234594
                              }
                            }
                          ]
                          boundingObject USE cylinder3
                          physics DEF phy1 Physics {
                            mass 1
                          }
                        }
                      ]
                      name "solid(1)"
                      boundingObject USE sphere1
                      physics USE phy1
                    }
                  ]
                  boundingObject USE cylinder2
                  physics USE phy1
                }
              ]
              boundingObject USE sphere1
              physics USE phy1
            }
          ]
          boundingObject USE cylinder1
          physics USE phy1
        }
      ]
      name "wheel2_left_system"
      physics USE phy1
    }
    Solid {
      translation -0.18 0.24 0
      children [
        Solid {
          translation -0.000177663 0.0173403 0.0599364
          rotation -0.9999999929357695 8.124469320562993e-05 -8.676267159571073e-05 1.5708626067521982
          children [
            DEF cylinder1 Shape {
              appearance DamascusSteel {
              }
              geometry Cylinder {
                height 0.09
                radius 0.02
              }
            }
            Solid {
              translation 0 0 0.05
              children [
                DEF sphere1 Shape {
                  appearance BrushedSteel {
                  }
                  geometry Sphere {
                    radius 0.02
                  }
                }
                Solid {
                  translation 0 0.1 1.79608e-07
                  rotation -1 0 0 -1.5707953071795862
                  children [
                    DEF cylinder2 Shape {
                      appearance BrushedSteel {
                      }
                      geometry Cylinder {
                        height 0.2
                        radius 0.02
                      }
                    }
                    Solid {
                      translation 0 0 -0.11
                      children [
                        DEF sphere1 Shape {
                          appearance BrushedSteel {
                          }
                          geometry Sphere {
                            radius 0.02
                          }
                        }
                        Solid {
                          translation 0 0.03 -9.99999e-08
                          rotation 1 0 0 1.5708
                          children [
                            DEF cylinder3 Shape {
                              appearance BrushedSteel {
                              }
                              geometry Cylinder {
                                height 0.06
                                radius 0.02
                              }
                            }
                            HingeJoint {
                              jointParameters HingeJointParameters {
                                position 188.078206052171
                                axis 0 0 1
                                anchor 0.00237208 0.000614304 -0.0799754
                              }
                              device [
                                RotationalMotor {
                                  name "wheel1_right"
                                }
                              ]
                              endPoint Solid {
                                translation 0.0008025431797617766 0.000581788979634643 -0.07997536572404963
                                rotation 0.5304841489013314 -0.847694855313626 6.264254453199266e-06 3.1415966018302046
                                children [
                                  DEF wheel Shape {
                                    appearance DamascusSteel {
                                    }
                                    geometry Cylinder {
                                      height 0.15
                                      radius 0.15
                                    }
                                  }
                                ]
                                boundingObject USE wheel
                                physics Physics {
                                  mass 1
                                }
                                linearVelocity 3.605926366155149e-05 -0.00017431773210260622 -3.617389884750768e-05
                                angularVelocity 0.0004371710077316474 -0.0002771759006853588 -0.0004013502809138036
                              }
                            }
                          ]
                          boundingObject USE cylinder3
                          physics DEF phy1 Physics {
                            mass 1
                          }
                        }
                      ]
                      name "solid(1)"
                      boundingObject USE sphere1
                      physics USE phy1
                    }
                  ]
                  boundingObject USE cylinder2
                  physics USE phy1
                }
              ]
              boundingObject USE sphere1
              physics USE phy1
            }
          ]
          boundingObject USE cylinder1
          physics USE phy1
        }
      ]
      name "wheel1_right_system"
      physics DEF phy1 Physics {
        mass 1
      }
    }
    Solid {
      translation 0.18 0.24 0
      children [
        Solid {
          translation -0.000177663 0.0173403 0.0599364
          rotation -0.9999999929357695 8.124469320562993e-05 -8.676267159571073e-05 1.5708626067521982
          children [
            DEF cylinder1 Shape {
              appearance DamascusSteel {
              }
              geometry Cylinder {
                height 0.09
                radius 0.02
              }
            }
            Solid {
              translation 0 0 0.05
              children [
                DEF sphere1 Shape {
                  appearance BrushedSteel {
                  }
                  geometry Sphere {
                    radius 0.02
                  }
                }
                Solid {
                  translation 0 0.1 1.79608e-07
                  rotation -1 0 0 -1.5707953071795862
                  children [
                    DEF cylinder2 Shape {
                      appearance BrushedSteel {
                      }
                      geometry Cylinder {
                        height 0.2
                        radius 0.02
                      }
                    }
                    Solid {
                      translation 0 0 -0.11
                      children [
                        DEF sphere1 Shape {
                          appearance BrushedSteel {
                          }
                          geometry Sphere {
                            radius 0.02
                          }
                        }
                        Solid {
                          translation 0 0.03 -9.99999e-08
                          rotation 1 0 0 1.5708
                          children [
                            DEF cylinder3 Shape {
                              appearance BrushedSteel {
                              }
                              geometry Cylinder {
                                height 0.06
                                radius 0.02
                              }
                            }
                            HingeJoint {
                              jointParameters HingeJointParameters {
                                position 183.86003607406053
                                axis 0 0 1
                                anchor 0.00237208 0.000614304 -0.0799754
                              }
                              device [
                                RotationalMotor {
                                  name "wheel2_right"
                                }
                              ]
                              endPoint Solid {
                                translation 0.003145205025225183 -0.0007519978524482172 -0.07997536572404963
                                rotation -0.9997819593956843 -0.020881419123874145 -1.5165245995217505e-06 3.1415798726371555
                                children [
                                  DEF wheel Shape {
                                    appearance DamascusSteel {
                                    }
                                    geometry Cylinder {
                                      height 0.15
                                      radius 0.15
                                    }
                                  }
                                ]
                                boundingObject USE wheel
                                physics Physics {
                                  mass 1
                                }
                                linearVelocity -0.00022643918384405775 -4.773637042570204e-05 -2.5688732510830755e-05
                                angularVelocity 0.0003820120225741839 -0.00033969911113085316 -0.00040920302471535587
                              }
                            }
                          ]
                          boundingObject USE cylinder3
                          physics DEF phy1 Physics {
                            mass 1
                          }
                        }
                      ]
                      name "solid(1)"
                      boundingObject USE sphere1
                      physics USE phy1
                    }
                  ]
                  boundingObject USE cylinder2
                  physics USE phy1
                }
              ]
              boundingObject USE sphere1
              physics USE phy1
            }
          ]
          boundingObject USE cylinder1
          physics USE phy1
        }
      ]
      name "wheel2_right_system"
      physics DEF phy1 Physics {
        mass 1
      }
    }
  ]
  boundingObject USE body
  physics DEF phy Physics {
    mass 1
  }
  controller "my_controller"
  linearVelocity 4.54255946801862e-06 -1.2715576532044144e-05 -1.7914854622502535e-05
  angularVelocity -2.4331542518899733e-05 1.0133729224750554e-05 2.2228284088922584e-05
}
